{
 "cells": [
  {
   "cell_type": "code",
   "execution_count": 20,
   "id": "38a125bc",
   "metadata": {},
   "outputs": [],
   "source": [
    "import requests"
   ]
  },
  {
   "cell_type": "code",
   "execution_count": 22,
   "id": "0b6dc970",
   "metadata": {},
   "outputs": [
    {
     "ename": "ConnectionError",
     "evalue": "('Connection aborted.', RemoteDisconnected('Remote end closed connection without response'))",
     "output_type": "error",
     "traceback": [
      "\u001b[0;31m---------------------------------------------------------------------------\u001b[0m",
      "\u001b[0;31mRemoteDisconnected\u001b[0m                        Traceback (most recent call last)",
      "File \u001b[0;32m~/anaconda3/lib/python3.11/site-packages/urllib3/connectionpool.py:714\u001b[0m, in \u001b[0;36mHTTPConnectionPool.urlopen\u001b[0;34m(self, method, url, body, headers, retries, redirect, assert_same_host, timeout, pool_timeout, release_conn, chunked, body_pos, **response_kw)\u001b[0m\n\u001b[1;32m    713\u001b[0m \u001b[38;5;66;03m# Make the request on the httplib connection object.\u001b[39;00m\n\u001b[0;32m--> 714\u001b[0m httplib_response \u001b[38;5;241m=\u001b[39m \u001b[38;5;28mself\u001b[39m\u001b[38;5;241m.\u001b[39m_make_request(\n\u001b[1;32m    715\u001b[0m     conn,\n\u001b[1;32m    716\u001b[0m     method,\n\u001b[1;32m    717\u001b[0m     url,\n\u001b[1;32m    718\u001b[0m     timeout\u001b[38;5;241m=\u001b[39mtimeout_obj,\n\u001b[1;32m    719\u001b[0m     body\u001b[38;5;241m=\u001b[39mbody,\n\u001b[1;32m    720\u001b[0m     headers\u001b[38;5;241m=\u001b[39mheaders,\n\u001b[1;32m    721\u001b[0m     chunked\u001b[38;5;241m=\u001b[39mchunked,\n\u001b[1;32m    722\u001b[0m )\n\u001b[1;32m    724\u001b[0m \u001b[38;5;66;03m# If we're going to release the connection in ``finally:``, then\u001b[39;00m\n\u001b[1;32m    725\u001b[0m \u001b[38;5;66;03m# the response doesn't need to know about the connection. Otherwise\u001b[39;00m\n\u001b[1;32m    726\u001b[0m \u001b[38;5;66;03m# it will also try to release it and we'll have a double-release\u001b[39;00m\n\u001b[1;32m    727\u001b[0m \u001b[38;5;66;03m# mess.\u001b[39;00m\n",
      "File \u001b[0;32m~/anaconda3/lib/python3.11/site-packages/urllib3/connectionpool.py:466\u001b[0m, in \u001b[0;36mHTTPConnectionPool._make_request\u001b[0;34m(self, conn, method, url, timeout, chunked, **httplib_request_kw)\u001b[0m\n\u001b[1;32m    462\u001b[0m         \u001b[38;5;28;01mexcept\u001b[39;00m \u001b[38;5;167;01mBaseException\u001b[39;00m \u001b[38;5;28;01mas\u001b[39;00m e:\n\u001b[1;32m    463\u001b[0m             \u001b[38;5;66;03m# Remove the TypeError from the exception chain in\u001b[39;00m\n\u001b[1;32m    464\u001b[0m             \u001b[38;5;66;03m# Python 3 (including for exceptions like SystemExit).\u001b[39;00m\n\u001b[1;32m    465\u001b[0m             \u001b[38;5;66;03m# Otherwise it looks like a bug in the code.\u001b[39;00m\n\u001b[0;32m--> 466\u001b[0m             six\u001b[38;5;241m.\u001b[39mraise_from(e, \u001b[38;5;28;01mNone\u001b[39;00m)\n\u001b[1;32m    467\u001b[0m \u001b[38;5;28;01mexcept\u001b[39;00m (SocketTimeout, BaseSSLError, SocketError) \u001b[38;5;28;01mas\u001b[39;00m e:\n",
      "File \u001b[0;32m<string>:3\u001b[0m, in \u001b[0;36mraise_from\u001b[0;34m(value, from_value)\u001b[0m\n",
      "File \u001b[0;32m~/anaconda3/lib/python3.11/site-packages/urllib3/connectionpool.py:461\u001b[0m, in \u001b[0;36mHTTPConnectionPool._make_request\u001b[0;34m(self, conn, method, url, timeout, chunked, **httplib_request_kw)\u001b[0m\n\u001b[1;32m    460\u001b[0m \u001b[38;5;28;01mtry\u001b[39;00m:\n\u001b[0;32m--> 461\u001b[0m     httplib_response \u001b[38;5;241m=\u001b[39m conn\u001b[38;5;241m.\u001b[39mgetresponse()\n\u001b[1;32m    462\u001b[0m \u001b[38;5;28;01mexcept\u001b[39;00m \u001b[38;5;167;01mBaseException\u001b[39;00m \u001b[38;5;28;01mas\u001b[39;00m e:\n\u001b[1;32m    463\u001b[0m     \u001b[38;5;66;03m# Remove the TypeError from the exception chain in\u001b[39;00m\n\u001b[1;32m    464\u001b[0m     \u001b[38;5;66;03m# Python 3 (including for exceptions like SystemExit).\u001b[39;00m\n\u001b[1;32m    465\u001b[0m     \u001b[38;5;66;03m# Otherwise it looks like a bug in the code.\u001b[39;00m\n",
      "File \u001b[0;32m~/anaconda3/lib/python3.11/http/client.py:1378\u001b[0m, in \u001b[0;36mHTTPConnection.getresponse\u001b[0;34m(self)\u001b[0m\n\u001b[1;32m   1377\u001b[0m \u001b[38;5;28;01mtry\u001b[39;00m:\n\u001b[0;32m-> 1378\u001b[0m     response\u001b[38;5;241m.\u001b[39mbegin()\n\u001b[1;32m   1379\u001b[0m \u001b[38;5;28;01mexcept\u001b[39;00m \u001b[38;5;167;01mConnectionError\u001b[39;00m:\n",
      "File \u001b[0;32m~/anaconda3/lib/python3.11/http/client.py:318\u001b[0m, in \u001b[0;36mHTTPResponse.begin\u001b[0;34m(self)\u001b[0m\n\u001b[1;32m    317\u001b[0m \u001b[38;5;28;01mwhile\u001b[39;00m \u001b[38;5;28;01mTrue\u001b[39;00m:\n\u001b[0;32m--> 318\u001b[0m     version, status, reason \u001b[38;5;241m=\u001b[39m \u001b[38;5;28mself\u001b[39m\u001b[38;5;241m.\u001b[39m_read_status()\n\u001b[1;32m    319\u001b[0m     \u001b[38;5;28;01mif\u001b[39;00m status \u001b[38;5;241m!=\u001b[39m CONTINUE:\n",
      "File \u001b[0;32m~/anaconda3/lib/python3.11/http/client.py:287\u001b[0m, in \u001b[0;36mHTTPResponse._read_status\u001b[0;34m(self)\u001b[0m\n\u001b[1;32m    284\u001b[0m \u001b[38;5;28;01mif\u001b[39;00m \u001b[38;5;129;01mnot\u001b[39;00m line:\n\u001b[1;32m    285\u001b[0m     \u001b[38;5;66;03m# Presumably, the server closed the connection before\u001b[39;00m\n\u001b[1;32m    286\u001b[0m     \u001b[38;5;66;03m# sending a valid response.\u001b[39;00m\n\u001b[0;32m--> 287\u001b[0m     \u001b[38;5;28;01mraise\u001b[39;00m RemoteDisconnected(\u001b[38;5;124m\"\u001b[39m\u001b[38;5;124mRemote end closed connection without\u001b[39m\u001b[38;5;124m\"\u001b[39m\n\u001b[1;32m    288\u001b[0m                              \u001b[38;5;124m\"\u001b[39m\u001b[38;5;124m response\u001b[39m\u001b[38;5;124m\"\u001b[39m)\n\u001b[1;32m    289\u001b[0m \u001b[38;5;28;01mtry\u001b[39;00m:\n",
      "\u001b[0;31mRemoteDisconnected\u001b[0m: Remote end closed connection without response",
      "\nDuring handling of the above exception, another exception occurred:\n",
      "\u001b[0;31mProtocolError\u001b[0m                             Traceback (most recent call last)",
      "File \u001b[0;32m~/anaconda3/lib/python3.11/site-packages/requests/adapters.py:486\u001b[0m, in \u001b[0;36mHTTPAdapter.send\u001b[0;34m(self, request, stream, timeout, verify, cert, proxies)\u001b[0m\n\u001b[1;32m    485\u001b[0m \u001b[38;5;28;01mtry\u001b[39;00m:\n\u001b[0;32m--> 486\u001b[0m     resp \u001b[38;5;241m=\u001b[39m conn\u001b[38;5;241m.\u001b[39murlopen(\n\u001b[1;32m    487\u001b[0m         method\u001b[38;5;241m=\u001b[39mrequest\u001b[38;5;241m.\u001b[39mmethod,\n\u001b[1;32m    488\u001b[0m         url\u001b[38;5;241m=\u001b[39murl,\n\u001b[1;32m    489\u001b[0m         body\u001b[38;5;241m=\u001b[39mrequest\u001b[38;5;241m.\u001b[39mbody,\n\u001b[1;32m    490\u001b[0m         headers\u001b[38;5;241m=\u001b[39mrequest\u001b[38;5;241m.\u001b[39mheaders,\n\u001b[1;32m    491\u001b[0m         redirect\u001b[38;5;241m=\u001b[39m\u001b[38;5;28;01mFalse\u001b[39;00m,\n\u001b[1;32m    492\u001b[0m         assert_same_host\u001b[38;5;241m=\u001b[39m\u001b[38;5;28;01mFalse\u001b[39;00m,\n\u001b[1;32m    493\u001b[0m         preload_content\u001b[38;5;241m=\u001b[39m\u001b[38;5;28;01mFalse\u001b[39;00m,\n\u001b[1;32m    494\u001b[0m         decode_content\u001b[38;5;241m=\u001b[39m\u001b[38;5;28;01mFalse\u001b[39;00m,\n\u001b[1;32m    495\u001b[0m         retries\u001b[38;5;241m=\u001b[39m\u001b[38;5;28mself\u001b[39m\u001b[38;5;241m.\u001b[39mmax_retries,\n\u001b[1;32m    496\u001b[0m         timeout\u001b[38;5;241m=\u001b[39mtimeout,\n\u001b[1;32m    497\u001b[0m         chunked\u001b[38;5;241m=\u001b[39mchunked,\n\u001b[1;32m    498\u001b[0m     )\n\u001b[1;32m    500\u001b[0m \u001b[38;5;28;01mexcept\u001b[39;00m (ProtocolError, \u001b[38;5;167;01mOSError\u001b[39;00m) \u001b[38;5;28;01mas\u001b[39;00m err:\n",
      "File \u001b[0;32m~/anaconda3/lib/python3.11/site-packages/urllib3/connectionpool.py:798\u001b[0m, in \u001b[0;36mHTTPConnectionPool.urlopen\u001b[0;34m(self, method, url, body, headers, retries, redirect, assert_same_host, timeout, pool_timeout, release_conn, chunked, body_pos, **response_kw)\u001b[0m\n\u001b[1;32m    796\u001b[0m     e \u001b[38;5;241m=\u001b[39m ProtocolError(\u001b[38;5;124m\"\u001b[39m\u001b[38;5;124mConnection aborted.\u001b[39m\u001b[38;5;124m\"\u001b[39m, e)\n\u001b[0;32m--> 798\u001b[0m retries \u001b[38;5;241m=\u001b[39m retries\u001b[38;5;241m.\u001b[39mincrement(\n\u001b[1;32m    799\u001b[0m     method, url, error\u001b[38;5;241m=\u001b[39me, _pool\u001b[38;5;241m=\u001b[39m\u001b[38;5;28mself\u001b[39m, _stacktrace\u001b[38;5;241m=\u001b[39msys\u001b[38;5;241m.\u001b[39mexc_info()[\u001b[38;5;241m2\u001b[39m]\n\u001b[1;32m    800\u001b[0m )\n\u001b[1;32m    801\u001b[0m retries\u001b[38;5;241m.\u001b[39msleep()\n",
      "File \u001b[0;32m~/anaconda3/lib/python3.11/site-packages/urllib3/util/retry.py:550\u001b[0m, in \u001b[0;36mRetry.increment\u001b[0;34m(self, method, url, response, error, _pool, _stacktrace)\u001b[0m\n\u001b[1;32m    549\u001b[0m \u001b[38;5;28;01mif\u001b[39;00m read \u001b[38;5;129;01mis\u001b[39;00m \u001b[38;5;28;01mFalse\u001b[39;00m \u001b[38;5;129;01mor\u001b[39;00m \u001b[38;5;129;01mnot\u001b[39;00m \u001b[38;5;28mself\u001b[39m\u001b[38;5;241m.\u001b[39m_is_method_retryable(method):\n\u001b[0;32m--> 550\u001b[0m     \u001b[38;5;28;01mraise\u001b[39;00m six\u001b[38;5;241m.\u001b[39mreraise(\u001b[38;5;28mtype\u001b[39m(error), error, _stacktrace)\n\u001b[1;32m    551\u001b[0m \u001b[38;5;28;01melif\u001b[39;00m read \u001b[38;5;129;01mis\u001b[39;00m \u001b[38;5;129;01mnot\u001b[39;00m \u001b[38;5;28;01mNone\u001b[39;00m:\n",
      "File \u001b[0;32m~/anaconda3/lib/python3.11/site-packages/urllib3/packages/six.py:769\u001b[0m, in \u001b[0;36mreraise\u001b[0;34m(tp, value, tb)\u001b[0m\n\u001b[1;32m    768\u001b[0m \u001b[38;5;28;01mif\u001b[39;00m value\u001b[38;5;241m.\u001b[39m__traceback__ \u001b[38;5;129;01mis\u001b[39;00m \u001b[38;5;129;01mnot\u001b[39;00m tb:\n\u001b[0;32m--> 769\u001b[0m     \u001b[38;5;28;01mraise\u001b[39;00m value\u001b[38;5;241m.\u001b[39mwith_traceback(tb)\n\u001b[1;32m    770\u001b[0m \u001b[38;5;28;01mraise\u001b[39;00m value\n",
      "File \u001b[0;32m~/anaconda3/lib/python3.11/site-packages/urllib3/connectionpool.py:714\u001b[0m, in \u001b[0;36mHTTPConnectionPool.urlopen\u001b[0;34m(self, method, url, body, headers, retries, redirect, assert_same_host, timeout, pool_timeout, release_conn, chunked, body_pos, **response_kw)\u001b[0m\n\u001b[1;32m    713\u001b[0m \u001b[38;5;66;03m# Make the request on the httplib connection object.\u001b[39;00m\n\u001b[0;32m--> 714\u001b[0m httplib_response \u001b[38;5;241m=\u001b[39m \u001b[38;5;28mself\u001b[39m\u001b[38;5;241m.\u001b[39m_make_request(\n\u001b[1;32m    715\u001b[0m     conn,\n\u001b[1;32m    716\u001b[0m     method,\n\u001b[1;32m    717\u001b[0m     url,\n\u001b[1;32m    718\u001b[0m     timeout\u001b[38;5;241m=\u001b[39mtimeout_obj,\n\u001b[1;32m    719\u001b[0m     body\u001b[38;5;241m=\u001b[39mbody,\n\u001b[1;32m    720\u001b[0m     headers\u001b[38;5;241m=\u001b[39mheaders,\n\u001b[1;32m    721\u001b[0m     chunked\u001b[38;5;241m=\u001b[39mchunked,\n\u001b[1;32m    722\u001b[0m )\n\u001b[1;32m    724\u001b[0m \u001b[38;5;66;03m# If we're going to release the connection in ``finally:``, then\u001b[39;00m\n\u001b[1;32m    725\u001b[0m \u001b[38;5;66;03m# the response doesn't need to know about the connection. Otherwise\u001b[39;00m\n\u001b[1;32m    726\u001b[0m \u001b[38;5;66;03m# it will also try to release it and we'll have a double-release\u001b[39;00m\n\u001b[1;32m    727\u001b[0m \u001b[38;5;66;03m# mess.\u001b[39;00m\n",
      "File \u001b[0;32m~/anaconda3/lib/python3.11/site-packages/urllib3/connectionpool.py:466\u001b[0m, in \u001b[0;36mHTTPConnectionPool._make_request\u001b[0;34m(self, conn, method, url, timeout, chunked, **httplib_request_kw)\u001b[0m\n\u001b[1;32m    462\u001b[0m         \u001b[38;5;28;01mexcept\u001b[39;00m \u001b[38;5;167;01mBaseException\u001b[39;00m \u001b[38;5;28;01mas\u001b[39;00m e:\n\u001b[1;32m    463\u001b[0m             \u001b[38;5;66;03m# Remove the TypeError from the exception chain in\u001b[39;00m\n\u001b[1;32m    464\u001b[0m             \u001b[38;5;66;03m# Python 3 (including for exceptions like SystemExit).\u001b[39;00m\n\u001b[1;32m    465\u001b[0m             \u001b[38;5;66;03m# Otherwise it looks like a bug in the code.\u001b[39;00m\n\u001b[0;32m--> 466\u001b[0m             six\u001b[38;5;241m.\u001b[39mraise_from(e, \u001b[38;5;28;01mNone\u001b[39;00m)\n\u001b[1;32m    467\u001b[0m \u001b[38;5;28;01mexcept\u001b[39;00m (SocketTimeout, BaseSSLError, SocketError) \u001b[38;5;28;01mas\u001b[39;00m e:\n",
      "File \u001b[0;32m<string>:3\u001b[0m, in \u001b[0;36mraise_from\u001b[0;34m(value, from_value)\u001b[0m\n",
      "File \u001b[0;32m~/anaconda3/lib/python3.11/site-packages/urllib3/connectionpool.py:461\u001b[0m, in \u001b[0;36mHTTPConnectionPool._make_request\u001b[0;34m(self, conn, method, url, timeout, chunked, **httplib_request_kw)\u001b[0m\n\u001b[1;32m    460\u001b[0m \u001b[38;5;28;01mtry\u001b[39;00m:\n\u001b[0;32m--> 461\u001b[0m     httplib_response \u001b[38;5;241m=\u001b[39m conn\u001b[38;5;241m.\u001b[39mgetresponse()\n\u001b[1;32m    462\u001b[0m \u001b[38;5;28;01mexcept\u001b[39;00m \u001b[38;5;167;01mBaseException\u001b[39;00m \u001b[38;5;28;01mas\u001b[39;00m e:\n\u001b[1;32m    463\u001b[0m     \u001b[38;5;66;03m# Remove the TypeError from the exception chain in\u001b[39;00m\n\u001b[1;32m    464\u001b[0m     \u001b[38;5;66;03m# Python 3 (including for exceptions like SystemExit).\u001b[39;00m\n\u001b[1;32m    465\u001b[0m     \u001b[38;5;66;03m# Otherwise it looks like a bug in the code.\u001b[39;00m\n",
      "File \u001b[0;32m~/anaconda3/lib/python3.11/http/client.py:1378\u001b[0m, in \u001b[0;36mHTTPConnection.getresponse\u001b[0;34m(self)\u001b[0m\n\u001b[1;32m   1377\u001b[0m \u001b[38;5;28;01mtry\u001b[39;00m:\n\u001b[0;32m-> 1378\u001b[0m     response\u001b[38;5;241m.\u001b[39mbegin()\n\u001b[1;32m   1379\u001b[0m \u001b[38;5;28;01mexcept\u001b[39;00m \u001b[38;5;167;01mConnectionError\u001b[39;00m:\n",
      "File \u001b[0;32m~/anaconda3/lib/python3.11/http/client.py:318\u001b[0m, in \u001b[0;36mHTTPResponse.begin\u001b[0;34m(self)\u001b[0m\n\u001b[1;32m    317\u001b[0m \u001b[38;5;28;01mwhile\u001b[39;00m \u001b[38;5;28;01mTrue\u001b[39;00m:\n\u001b[0;32m--> 318\u001b[0m     version, status, reason \u001b[38;5;241m=\u001b[39m \u001b[38;5;28mself\u001b[39m\u001b[38;5;241m.\u001b[39m_read_status()\n\u001b[1;32m    319\u001b[0m     \u001b[38;5;28;01mif\u001b[39;00m status \u001b[38;5;241m!=\u001b[39m CONTINUE:\n",
      "File \u001b[0;32m~/anaconda3/lib/python3.11/http/client.py:287\u001b[0m, in \u001b[0;36mHTTPResponse._read_status\u001b[0;34m(self)\u001b[0m\n\u001b[1;32m    284\u001b[0m \u001b[38;5;28;01mif\u001b[39;00m \u001b[38;5;129;01mnot\u001b[39;00m line:\n\u001b[1;32m    285\u001b[0m     \u001b[38;5;66;03m# Presumably, the server closed the connection before\u001b[39;00m\n\u001b[1;32m    286\u001b[0m     \u001b[38;5;66;03m# sending a valid response.\u001b[39;00m\n\u001b[0;32m--> 287\u001b[0m     \u001b[38;5;28;01mraise\u001b[39;00m RemoteDisconnected(\u001b[38;5;124m\"\u001b[39m\u001b[38;5;124mRemote end closed connection without\u001b[39m\u001b[38;5;124m\"\u001b[39m\n\u001b[1;32m    288\u001b[0m                              \u001b[38;5;124m\"\u001b[39m\u001b[38;5;124m response\u001b[39m\u001b[38;5;124m\"\u001b[39m)\n\u001b[1;32m    289\u001b[0m \u001b[38;5;28;01mtry\u001b[39;00m:\n",
      "\u001b[0;31mProtocolError\u001b[0m: ('Connection aborted.', RemoteDisconnected('Remote end closed connection without response'))",
      "\nDuring handling of the above exception, another exception occurred:\n",
      "\u001b[0;31mConnectionError\u001b[0m                           Traceback (most recent call last)",
      "Cell \u001b[0;32mIn[22], line 3\u001b[0m\n\u001b[1;32m      1\u001b[0m url \u001b[38;5;241m=\u001b[39m \u001b[38;5;124m\"\u001b[39m\u001b[38;5;124mhttp://localhost:9696\u001b[39m\u001b[38;5;124m\"\u001b[39m\n\u001b[1;32m      2\u001b[0m client \u001b[38;5;241m=\u001b[39m {\u001b[38;5;124m\"\u001b[39m\u001b[38;5;124mjob\u001b[39m\u001b[38;5;124m\"\u001b[39m: \u001b[38;5;124m\"\u001b[39m\u001b[38;5;124mretired\u001b[39m\u001b[38;5;124m\"\u001b[39m, \u001b[38;5;124m\"\u001b[39m\u001b[38;5;124mduration\u001b[39m\u001b[38;5;124m\"\u001b[39m: \u001b[38;5;241m445\u001b[39m, \u001b[38;5;124m\"\u001b[39m\u001b[38;5;124mpoutcome\u001b[39m\u001b[38;5;124m\"\u001b[39m: \u001b[38;5;124m\"\u001b[39m\u001b[38;5;124msuccess\u001b[39m\u001b[38;5;124m\"\u001b[39m}\n\u001b[0;32m----> 3\u001b[0m requests\u001b[38;5;241m.\u001b[39mpost(url, json\u001b[38;5;241m=\u001b[39mclient)\u001b[38;5;241m.\u001b[39mjson()\n",
      "File \u001b[0;32m~/anaconda3/lib/python3.11/site-packages/requests/api.py:115\u001b[0m, in \u001b[0;36mpost\u001b[0;34m(url, data, json, **kwargs)\u001b[0m\n\u001b[1;32m    103\u001b[0m \u001b[38;5;28;01mdef\u001b[39;00m \u001b[38;5;21mpost\u001b[39m(url, data\u001b[38;5;241m=\u001b[39m\u001b[38;5;28;01mNone\u001b[39;00m, json\u001b[38;5;241m=\u001b[39m\u001b[38;5;28;01mNone\u001b[39;00m, \u001b[38;5;241m*\u001b[39m\u001b[38;5;241m*\u001b[39mkwargs):\n\u001b[1;32m    104\u001b[0m \u001b[38;5;250m    \u001b[39m\u001b[38;5;124mr\u001b[39m\u001b[38;5;124;03m\"\"\"Sends a POST request.\u001b[39;00m\n\u001b[1;32m    105\u001b[0m \n\u001b[1;32m    106\u001b[0m \u001b[38;5;124;03m    :param url: URL for the new :class:`Request` object.\u001b[39;00m\n\u001b[0;32m   (...)\u001b[0m\n\u001b[1;32m    112\u001b[0m \u001b[38;5;124;03m    :rtype: requests.Response\u001b[39;00m\n\u001b[1;32m    113\u001b[0m \u001b[38;5;124;03m    \"\"\"\u001b[39;00m\n\u001b[0;32m--> 115\u001b[0m     \u001b[38;5;28;01mreturn\u001b[39;00m request(\u001b[38;5;124m\"\u001b[39m\u001b[38;5;124mpost\u001b[39m\u001b[38;5;124m\"\u001b[39m, url, data\u001b[38;5;241m=\u001b[39mdata, json\u001b[38;5;241m=\u001b[39mjson, \u001b[38;5;241m*\u001b[39m\u001b[38;5;241m*\u001b[39mkwargs)\n",
      "File \u001b[0;32m~/anaconda3/lib/python3.11/site-packages/requests/api.py:59\u001b[0m, in \u001b[0;36mrequest\u001b[0;34m(method, url, **kwargs)\u001b[0m\n\u001b[1;32m     55\u001b[0m \u001b[38;5;66;03m# By using the 'with' statement we are sure the session is closed, thus we\u001b[39;00m\n\u001b[1;32m     56\u001b[0m \u001b[38;5;66;03m# avoid leaving sockets open which can trigger a ResourceWarning in some\u001b[39;00m\n\u001b[1;32m     57\u001b[0m \u001b[38;5;66;03m# cases, and look like a memory leak in others.\u001b[39;00m\n\u001b[1;32m     58\u001b[0m \u001b[38;5;28;01mwith\u001b[39;00m sessions\u001b[38;5;241m.\u001b[39mSession() \u001b[38;5;28;01mas\u001b[39;00m session:\n\u001b[0;32m---> 59\u001b[0m     \u001b[38;5;28;01mreturn\u001b[39;00m session\u001b[38;5;241m.\u001b[39mrequest(method\u001b[38;5;241m=\u001b[39mmethod, url\u001b[38;5;241m=\u001b[39murl, \u001b[38;5;241m*\u001b[39m\u001b[38;5;241m*\u001b[39mkwargs)\n",
      "File \u001b[0;32m~/anaconda3/lib/python3.11/site-packages/requests/sessions.py:589\u001b[0m, in \u001b[0;36mSession.request\u001b[0;34m(self, method, url, params, data, headers, cookies, files, auth, timeout, allow_redirects, proxies, hooks, stream, verify, cert, json)\u001b[0m\n\u001b[1;32m    584\u001b[0m send_kwargs \u001b[38;5;241m=\u001b[39m {\n\u001b[1;32m    585\u001b[0m     \u001b[38;5;124m\"\u001b[39m\u001b[38;5;124mtimeout\u001b[39m\u001b[38;5;124m\"\u001b[39m: timeout,\n\u001b[1;32m    586\u001b[0m     \u001b[38;5;124m\"\u001b[39m\u001b[38;5;124mallow_redirects\u001b[39m\u001b[38;5;124m\"\u001b[39m: allow_redirects,\n\u001b[1;32m    587\u001b[0m }\n\u001b[1;32m    588\u001b[0m send_kwargs\u001b[38;5;241m.\u001b[39mupdate(settings)\n\u001b[0;32m--> 589\u001b[0m resp \u001b[38;5;241m=\u001b[39m \u001b[38;5;28mself\u001b[39m\u001b[38;5;241m.\u001b[39msend(prep, \u001b[38;5;241m*\u001b[39m\u001b[38;5;241m*\u001b[39msend_kwargs)\n\u001b[1;32m    591\u001b[0m \u001b[38;5;28;01mreturn\u001b[39;00m resp\n",
      "File \u001b[0;32m~/anaconda3/lib/python3.11/site-packages/requests/sessions.py:703\u001b[0m, in \u001b[0;36mSession.send\u001b[0;34m(self, request, **kwargs)\u001b[0m\n\u001b[1;32m    700\u001b[0m start \u001b[38;5;241m=\u001b[39m preferred_clock()\n\u001b[1;32m    702\u001b[0m \u001b[38;5;66;03m# Send the request\u001b[39;00m\n\u001b[0;32m--> 703\u001b[0m r \u001b[38;5;241m=\u001b[39m adapter\u001b[38;5;241m.\u001b[39msend(request, \u001b[38;5;241m*\u001b[39m\u001b[38;5;241m*\u001b[39mkwargs)\n\u001b[1;32m    705\u001b[0m \u001b[38;5;66;03m# Total elapsed time of the request (approximately)\u001b[39;00m\n\u001b[1;32m    706\u001b[0m elapsed \u001b[38;5;241m=\u001b[39m preferred_clock() \u001b[38;5;241m-\u001b[39m start\n",
      "File \u001b[0;32m~/anaconda3/lib/python3.11/site-packages/requests/adapters.py:501\u001b[0m, in \u001b[0;36mHTTPAdapter.send\u001b[0;34m(self, request, stream, timeout, verify, cert, proxies)\u001b[0m\n\u001b[1;32m    486\u001b[0m     resp \u001b[38;5;241m=\u001b[39m conn\u001b[38;5;241m.\u001b[39murlopen(\n\u001b[1;32m    487\u001b[0m         method\u001b[38;5;241m=\u001b[39mrequest\u001b[38;5;241m.\u001b[39mmethod,\n\u001b[1;32m    488\u001b[0m         url\u001b[38;5;241m=\u001b[39murl,\n\u001b[0;32m   (...)\u001b[0m\n\u001b[1;32m    497\u001b[0m         chunked\u001b[38;5;241m=\u001b[39mchunked,\n\u001b[1;32m    498\u001b[0m     )\n\u001b[1;32m    500\u001b[0m \u001b[38;5;28;01mexcept\u001b[39;00m (ProtocolError, \u001b[38;5;167;01mOSError\u001b[39;00m) \u001b[38;5;28;01mas\u001b[39;00m err:\n\u001b[0;32m--> 501\u001b[0m     \u001b[38;5;28;01mraise\u001b[39;00m \u001b[38;5;167;01mConnectionError\u001b[39;00m(err, request\u001b[38;5;241m=\u001b[39mrequest)\n\u001b[1;32m    503\u001b[0m \u001b[38;5;28;01mexcept\u001b[39;00m MaxRetryError \u001b[38;5;28;01mas\u001b[39;00m e:\n\u001b[1;32m    504\u001b[0m     \u001b[38;5;28;01mif\u001b[39;00m \u001b[38;5;28misinstance\u001b[39m(e\u001b[38;5;241m.\u001b[39mreason, ConnectTimeoutError):\n\u001b[1;32m    505\u001b[0m         \u001b[38;5;66;03m# TODO: Remove this in 3.0.0: see #2811\u001b[39;00m\n",
      "\u001b[0;31mConnectionError\u001b[0m: ('Connection aborted.', RemoteDisconnected('Remote end closed connection without response'))"
     ]
    }
   ],
   "source": [
    "url = \"http://localhost:9696\"\n",
    "client = {\"job\": \"retired\", \"duration\": 445, \"poutcome\": \"success\"}\n",
    "requests.post(url, json=client).json()"
   ]
  },
  {
   "cell_type": "code",
   "execution_count": null,
   "id": "1b8fff30",
   "metadata": {},
   "outputs": [],
   "source": []
  },
  {
   "cell_type": "code",
   "execution_count": null,
   "id": "385b5bbf",
   "metadata": {},
   "outputs": [],
   "source": []
  }
 ],
 "metadata": {
  "kernelspec": {
   "display_name": "Python 3 (ipykernel)",
   "language": "python",
   "name": "python3"
  },
  "language_info": {
   "codemirror_mode": {
    "name": "ipython",
    "version": 3
   },
   "file_extension": ".py",
   "mimetype": "text/x-python",
   "name": "python",
   "nbconvert_exporter": "python",
   "pygments_lexer": "ipython3",
   "version": "3.11.4"
  }
 },
 "nbformat": 4,
 "nbformat_minor": 5
}
